Workbook

Sheet S1 Datalog+Results
A1: ID | B1: Nationality | C1: Gender | D1: Age | E1: Audio file | F1: Date | G1: Start Physiological recording | H1: #1 Start 1.Baseline S1 | I1: #2 End 1.Baseline S1 | J1: #1 ECG - SDNN | K1: ECG-RMSSD | L1: #2 EDA - SCR onset | M1: # 3 EDA - SCR latency or rise time | N1: #4 EDA - SCR peak amplitude | O1: # 5 EDA - SCR peak prominence | P1: Start DSP FW S1 | Q1: End DSP FW S1 | R1: Trials DSP FW | S1: Correct trials DSP FW | T1: #6 ECG - SDNN | U1: ECG-RMSSD | V1: #7 EDA - SCR onset | W1: # 8 EDA - SCR latency or rise time | X1: #9 EDA - SCR peak amplitude | Y1: # 10 EDA - SCR peak prominence | Z1: #3 Start 2.Baseline S1 | AA1: #4 End 2. Baseline S1 | AB1: #11 ECG - SDNN | AC1: ECG - RMSSD | AD1: #12 EDA - SCR onset | AE1: # 13 EDA - SCR latency or rise time | AF1: #14 EDA - SCR peak amplitude | AG1: # 15 EDA - SCR peak prominence | AH1: Start DSP BW S1 | AI1: End DSP BW S1 | AJ1: Trials DSP BW | AK1: Correct trials DSP BW | AL1: #16 ECG - SDNN | AM1: ECG - RMSSD | AN1: #17 EDA - SCR onset | AO1: # 18 EDA - SCR latency or rise time | AP1: #19 EDA - SCR peak amplitude | AQ1: # 20 EDA - SCR peak prominence | AR1: #5 Start 3. Baseline S1 | AS1: #6 End 3. Baseline S1 | AT1: #21 ECG - SDNN | AU1: ECG - RMSSD | AV1: #22 EDA - SCR onset | AW1: # 23 EDA - SCR latency or rise time | AX1: #24 EDA - SCR peak amplitude | AY1: # 25 EDA - SCR peak prominence | AZ1: Start Memo S1 | BA1: End Memo S1 | BB1: AIsYourMemoryTriggeredByASpecificSoundOrOverallSoundscapeSoundS | BC1: IfSoundPleaseSpecifyleaveBlankIfNotApplicable | BD1: BDescribeYourMemoryInAsMuchDetailAsPossible | BE1: CIsThisAMeaningfulEventYesNo | BF1: IfYesSpecifyOtherwiseWriteNone | BG1: DIsThisConnectedToAPersonYesNo | BH1: IfYesSpecifyOtherwiseWriteNone_1 | BI1: EIsThisAssociatedWithAPlaceYesNo | BJ1: IfYesSpecifyOtherwiseWriteNone_2 | BK1: FIsThisLinkedToAnActivityYesNo | BL1: IfYesSpecifyOtherwiseWriteNone_3 | BM1: GIsThisAssociatedWithAnObjectYesNo | BN1: IfYesSpecifyOtherwiseWriteNone_4 | BO1: HIsThisConnectedToASpecificTimeYesNo | BP1: IfYesSpecifyOtherwiseWriteNone_5 | BQ1: IIsThisAssociatedWithAThoughtYesNo | BR1: IfYesSpecifyOtherwiseWriteNone_6 | BS1: JIsThisConnectedToAnEmotionYesNo | BT1: IfYesSpecifyOtherwiseWriteNone_7 | BU1: ToWhatExtentIsThePresentSoundEnvironmentAppropriateToThePlacePl | BV1: DoesTheSoundscapeEvokeAnyEmotionsIfYesWhichOnes | BW1: Agreement_PLEASANT | BX1: Agreement_CHAOTIC | BY1: Agreement_VIBRANT | BZ1: Agreement_UNEVENTFUL | CA1: Agreement_CALM | CB1: Agreement_ANNOYING | CC1: Agreement_EVENTFUL | CD1: Agreement_MONOTONOUS | CE1: Agreement_QUIET | CF1: Agreement_UNCOMFORTABLE | CG1: Agreement_COMFORTABLE | CH1: Agreement_NOTANNOYING | CI1: Agreement_NOISY | CJ1: Agreement_EXHAUSTING | CK1: Agreement_RELAXING | CL1: Intensity_MechanicalSounds | CM1: Intensity_HumanSounds | CN1: Intensity_NaturalSounds | CO1: #26 ECG - SDNN | CP1: ECG - RMSSD | CQ1: #27 EDA - SCR onset | CR1: # 28 EDA - SCR latency or rise time | CS1: #29 EDA - SCR peak amplitude | CT1: # 30 EDA - SCR peak prominence
A2: 1 | B2: Turkey | C2: male | D2: 36 | E2: Te0 | F2: 11.12.2025 | G2: 0.59134259 | H2: 0.6 | I2: 0.60138889 | J2: 346.11453 | K2: 412.97972 | L2: 59.497262 | M2: 0.48764286 | N2: 0.0104508 | O2: 0.021333139 | P2: 0.60208333 | Q2: 0.60341435 | R2: 5 | S2: 4 | T2: 96.483194 | U2: 129.53354 | V2: 56.144023 | W2: 0.50135632 | X2: 0.0080647733 | Y2: 0.016028141 | Z2: 0.60347222 | AA2: 0.60416667 | AB2: 200.58416 | AC2: 262.50767 | AD2: 29.572356 | AE2: 0.55111111 | AF2: 0.0091131882 | AG2: 0.021250295 | AH2: 0.60417824 | AI2: 0.60550926 | AJ2: 5 | AK2: 4 | AL2: 59.913145 | AM2: 60.130907 | AN2: 57.469205 | AO2: 0.5673494 | AP2: 0.0091395096 | AQ2: 0.018714861 | AR2: 0.60486111 | AS2: 0.60625 | AT2: 204.26521 | AU2: 292.3942 | AV2: 28.829378 | AW2: 0.58137778 | AX2: 0.0093262409 | AY2: 0.023177434 | AZ2: 0.60625 | BA2: 0.60972222 | BB2: NA | BC2: NA | BD2: NA | BE2: NA | BF2: NA | BG2: NA | BH2: NA | BI2: NA | BJ2: NA | BK2: NA | BL2: NA | BM2: NA | BN2: NA | BO2: NA | BP2: NA | BQ2: NA | BR2: NA | BS2: NA | BT2: NA | BU2: NA | BV2: NA | BW2: NA | BX2: NA | BY2: NA | BZ2: NA | CA2: NA | CB2: NA | CC2: NA | CD2: NA | CE2: NA | CF2: NA | CG2: NA | CH2: NA | CI2: NA | CJ2: NA | CK2: NA | CL2: NA | CM2: NA | CN2: NA | CO2: 143.26627 | CP2: 192.60168 | CQ2: 148.56609 | CR2: 0.54326512 | CS2: 0.0070842973 | CT2: 0.013794974
A3: 2 | B3: China | C3: male | D3: 24 | E3: Te0 | F3: 12.12.2025 | G3: 0.44652778 | H3: 0.44652778 | I3: 0.44791667 | J3: 126.05763 | K3: 133.88948 | L3: 60.837152 | M3: 0.48313043 | N3: 0.0055871998 | O3: 0.010616226 | P3: 0.44930556 | Q3: 0.45037037 | R3: 7 | S3: 7 | T3: 52.570188 | U3: 43.826564 | V3: 47.258733 | W3: 0.49143333 | X3: 0.0056631193 | Y3: 0.01203454 | Z3: 0.45069444 | AA3: 0.45208333 | AB3: 120.60908 | AC3: 86.354071 | AD3: 60.103097 | AE3: 0.5032043 | AF3: 0.0055875306 | AG3: 0.011182446 | AH3: 0.45209491 | AI3: 0.45293981 | AJ3: 5 | AK3: 4 | AL3: 227.26774 | AM3: 178.97324 | AN3: 35.003286 | AO3: 0.45014286 | AP3: 0.0060734998 | AQ3: 0.012881668 | AR3: 0.45277778 | AS3: 0.45416667 | AT3: 134.53524 | AU3: 89.842357 | AV3: 53.296765 | AW3: 0.47703704 | AX3: 0.0061035187 | AY3: 0.012060482 | AZ3: 0.45416667 | BA3: 0.46041667 | BB3: yes | BC3: nervous | BD3: it is a little bit noisy for me | BE3: yes | BF3: it is hard for me to remumber the number | BG3: no | BH3: none | BI3: yes | BJ3: street | BK3: no | BL3: none | BM3: no | BN3: none | BO3: yes | BP3: in the morning | BQ3: no | BR3: none | BS3: yes | BT3: nervous | BU3: 80% | BV3: yes nervous | BW3: Disagree | BX3: Agree | BY3: Agree | BZ3: Agree | CA3: Strongly disagree | CB3: Strongly agree | CC3: Disagree | CD3: Disagree | CE3: Strongly disagree | CF3: Agree | CG3: Disagree | CH3: Disagree | CI3: Strongly agree | CJ3: Strongly disagree | CK3: Strongly disagree | CL3: Dominates completely | CM3: Not at all | CN3: A little | CP3: 152.07599 | CQ3: 271.902 | CR3: 0.49706667 | CS3: 0.006644354 | CT3: 0.011511555
A4: 3 | B4: Singapore | C4: male | D4: 21 | E4: TE0+SL+10 | F4: 12.12.2025 | G4: 0.56918981 | H4: 0.57083333 | I4: 0.57222222 | J4: 381.19984 | K4: 408.72974 | L4: 58.293079 | M4: 0.55060674 | N4: 0.0060616972 | O4: 0.012540368 | P4: 0.57271991 | Q4: 0.57386574 | R4: 7 | S4: 7 | T4: 377.19035 | U4: 524.58266 | V4: 48.496055 | W4: 0.46027397 | X4: 0.0058369454 | Y4: 0.012550341 | Z4: 0.57387731 | AA4: 0.57525463 | AB4: 68.569501 | AC4: 84.436494 | AD4: 58.712135 | AE4: 0.5212809 | AF4: 0.0069602332 | AG4: 0.013572972 | AH4: 0.57597222 | AI4: 0.57695602 | AJ4: 6 | AK4: 6 | AL4: 0 | AM4: 850.66621 | AN4: 41.934469 | AO4: 0.47746875 | AP4: 0.0075365238 | AQ4: 0.015648135 | AR4: 0.57708333 | AS4: 0.57847222 | AT4: 66.336313 | AU4: 78.373129 | AV4: 60.751416 | AW4: 0.43222472 | AX4: 0.0074523027 | AY4: 0.014388819 | AZ4: 0.57847222 | BA4: 0.58263889 | BB4: no | BC4: none | BD4: none | BE4: no | BF4: none | BG4: no | BH4: none | BI4: yes | BJ4: farm | BK4: no | BL4: none | BM4: yes | BN4: vehicles | BO4: no | BP4: none | BQ4: no | BR4: none | BS4: no | BT4: none | BU4: 70 | BV4: no | BW4: Disagree | BX4: Agree | BY4: Neither | BZ4: Neither | CA4: Disagree | CB4: Agree | CC4: Neither | CD4: Agree | CE4: Strongly disagree | CF4: Neither | CG4: Neither | CH4: Neither | CI4: Agree | CJ4: Neither | CK4: Disagree | CL4: Moderately | CM4: Not at all | CN4: A little | CO4: 261.99071 | CP4: 349.85938 | CQ4: 178.25945 | CR4: 0.49333829 | CS4: 0.0067489139 | CT4: 0.012373552
A5: 4 | B5: China | C5: female | D5: 28 | E5: Te0-10 | F5: 15.12.2025 | G5: 0.46399306 | H5: 0.46597222 | I5: 0.46736111 | J5: 33.486555 | K5: 17.405527 | L5: 59.436211 | M5: 0.51036842 | N5: 0.021444647 | O5: 0.060708116 | P5: 0.46832176 | Q5: 0.46945602 | R5: 6 | S5: 6 | T5: 89.015547 | U5: 88.644566 | V5: 49.332697 | W5: 0.50836364 | X5: 0.02072602 | Y5: 0.064014281 | Z5: 0.46946759 | AA5: 0.47084491 | AB5: 80.204881 | AC5: 86.931734 | AD5: 58.375625 | AE5: 0.5087 | AF5: 0.019415034 | AG5: 0.055553844 | AH5: 0.47107639 | AI5: 0.47209491 | AJ5: 6 | AK5: 5 | AL5: 117.18343 | AM5: 760.19661 | AN5: 43.674909 | AO5: 0.55763636 | AP5: 0.018907514 | AQ5: 0.0608233 | AR5: 0.47222222 | AS5: 0.47361111 | AU5: 156.41982 | AV5: 60.692909 | AW5: 0.52345455 | AX5: 0.01668852 | AY5: 0.052532315 | AZ5: 0.47361111 | BA5: 0.47777778 | BB5: Soundscape | BC5: None | BD5: I can't remeber the long numbers in the reverse section. | BE5: Yes | BF5: It's the memory stuff but not caused by the background music. | BG5: No | BH5: None | BI5: No | BJ5: None | BK5: No | BL5: None | BM5: No | BN5: None | BO5: Yes | BP5: A specific year | BQ5: No | BR5: None | BS5: No | BT5: None | BU5: 20% | BV5: Yes, relaxed. | BW5: Agree | BX5: Disagree | BY5: Disagree | BZ5: Agree | CA5: Neither | CB5: Agree | CC5: Neither | CD5: Neither | CE5: Disagree | CF5: Neither | CG5: Agree | CH5: Disagree | CI5: Disagree | CJ5: Neither | CK5: Agree | CL5: Moderately | CM5: Not at all | CN5: Moderately | CO5: 147.58714 | CP5: 195.80829 | CQ5: 179.7704 | CR5: 0.51910169 | CS5: 0.013855459 | CT5: 0.027744544
A6: 5 | B6: German | C6: female | D6: 41 | E6: TE0+HF+6 | F6: 15.12.2025 | G6: 0.56997685 | H6: 0.57152778 | I6: 0.57291667 | J6: 51.882485 | K6: 64.169697 | L6: 60.494831 | M6: 0.57029213 | N6: 0.0075153147 | O6: 0.01688597 | P6: 0.57347222 | Q6: 0.57415509 | R6: 5 | S6: 4 | T6: 38.825555 | V6: 28.509273 | W6: 0.47013636 | X6: 0.0073973588 | Y6: 0.021401987 | Z6: 0.57416667 | AA6: 0.57513889 | AC6: 613.30359 | AD6: 41.335969 | AE6: 0.4776875 | AF6: 0.0065180287 | AG6: 0.016779245 | AH6: 0.57515046 | AI6: 0.57638889 | AJ6: 7 | AK6: 6 | AL6: 10.408607 | AM6: 5.0485448 | AN6: 52.706198 | AO6: 0.50195062 | AP6: 0.0063190886 | AQ6: 0.015378332 | AR6: 0.57638889 | AS6: 0.57777778 | AT6: 35.083128 | AU6: 11.311604 | AV6: 58.829227 | AW6: 0.46009091 | AX6: 0.0061192594 | AY6: 0.015220376 | AZ6: 0.57777778 | BA6: 0.58055556 | BB6: sound | BC6: traffic | BD6: big city, urban traffic , rush hours | BE6: no | BF6: none | BG6: no | BH6: none | BI6: yes | BJ6: big cities | BK6: yes | BL6: walking | BM6: yes | BN6: vehicles | BO6: yes | BP6: daytime | BQ6: yes | BR6: hectic | BS6: yes | BT6: annoaynace, nervousness | BU6: 60% | BV6: mixture of calm and annoyance | BW6: Neither | BX6: Agree | BY6: Agree | BZ6: Disagree | CA6: Disagree | CB6: Agree | CC6: Agree | CD6: Neither | CE6: Disagree | CF6: Neither | CG6: Neither | CH6: Neither | CI6: Neither | CJ6: Agree | CK6: Neither | CL6: Dominates completely | CM6: Not at all | CN6: Moderately | CO6: 21.725906 | CP6: 9.4592815 | CQ6: 118.89312 | CR6: 0.50049162 | CS6: 0.0056145284 | CT6: 0.012922813
A7: 6 | B7: India | C7: male | D7: 28 | E7: TE0+SL+10 | F7: 15.12.2025 | G7: 0.63626157 | H7: 0.63680556 | I7: 0.63819444 | J7: 71.300039 | K7: 71.561055 | L7: 59.174813 | M7: 0.46197802 | N7: 0.010678407 | O7: 0.019314231 | P7: 0.63820602 | Q7: 0.63940972 | R7: 6 | S7: 6 | T7: 64.871459 | U7: 67.668372 | V7: 51.504494 | W7: 0.53080519 | X7: 0.010366833 | Y7: 0.018472883 | Z7: 0.63958333 | AA7: 0.64097222 | AB7: 114.1329 | AC7: 126.43938 | AD7: 59.889222 | AE7: 0.54148889 | AF7: 0.0090576422 | AG7: 0.017100836 | AH7: 0.6409838 | AI7: 0.64181713 | AJ7: 5 | AK7: 4 | AL7: 86.775674 | AM7: 124.71418 | AN7: 35.690286 | AO7: 0.46932143 | AP7: 0.0083578974 | AQ7: 0.015178517 | AR7: 0.64166667 | AS7: 0.64305556 | AT7: 90.84664 | AU7: 101.35834 | AV7: 51.405171 | AW7: 0.5082439 | AX7: 0.0093259662 | AY7: 0.018338088 | AZ7: 0.64305556 | BA7: 0.64583333 | BB7: No | BC7: None | BD7: my memory is good enough | BE7: NO | BF7: None | BG7: NO | BH7: None | BI7: No | BJ7: None | BK7: No | BL7: None | BM7: No | BN7: NONE | BO7: No | BP7: None | BQ7: No | BR7: None | BS7: No | BT7: None | BU7: 75 | BV7: No, not really | BW7: Disagree | BX7: Agree | BY7: Disagree | BZ7: Strongly disagree | CA7: Strongly disagree | CB7: Agree | CC7: Agree | CD7: Neither | CE7: Strongly disagree | CF7: Agree | CG7: Strongly disagree | CH7: Disagree | CI7: Agree | CJ7: Agree | CK7: Strongly disagree | CL7: A lot | CM7: Not at all | CN7: Moderately | CO7: 56.899433 | CP7: 53.837203 | CQ7: 116.22596 | CR7: 0.52480702 | CS7: 0.0095075109 | CT7: 0.017555202
A8: 7 | B8: German | C8: male | D8: 27 | E8: TE0 | F8: 16.12.2025 | G8: 0.45996528 | H8: 0.46597222 | I8: 0.46736111 | J8: 101.93327 | K8: 125.22911 | L8: 59.717205 | M8: 0.50988636 | N8: 0.011098812 | O8: 0.024907062 | P8: 0.47083333 | Q8: 0.47226852 | R8: 7 | S8: 6 | T8: 66.769541 | U8: 55.822625 | V8: 61.190667 | W8: 0.5515914 | X8: 0.011962868 | Y8: 0.027260458 | Z8: 0.47228009 | AA8: 0.47365741 | AB8: 0 | AD8: 59.530114 | AE8: 0.53843182 | AF8: 0.011731118 | AG8: 0.026678558 | AH8: 0.47366898 | AI8: 0.47480324 | AJ8: 6 | AK8: 5 | AL8: 359.78939 | AM8: 522.98642 | AN8: 47.768411 | AO8: 0.4910411 | AP8: 0.011218401 | AQ8: 0.030235747 | AR8: 0.47430556 | AS8: 0.47569444 | AT8: 255.21016 | AU8: 335.33289 | AV8: 37.987322 | AW8: 0.55532203 | AX8: 0.010840296 | AY8: 0.027486419 | AZ8: 0.47569444 | BA8: 0.48194444 | BB8: ja, Klanglandschaft | BC8: keine | BD8: Ist wie ein Spa Besuch, Saunabesuch (da kommt so entspannte Musik) | BE8: nein | BF8: keine | BG8: nein | BH8: keine | BI8: ja | BJ8: Sauna/ Spa Center | BK8: ja | BL8: saunieren | BM8: nein | BN8: keine | BO8: nein | BP8: keine | BQ8: ja | BR8: eher so Entspannung, tatsächlich eher "weniger Gedanken" | BS8: ja | BT8: so pure Zufriedenheit | BU8: 1 | BV8: generell mit Verkehrsgeräuschen eher so ein Mix aus Stress und Zufriedenheit | BW8: Weder noch | BX8: Stimme nicht zu | BY8: Stimme zu | BZ8: Stimme überhaupt nicht zu | CA8: Stimme überhaupt nicht zu | CB8: Weder noch | CC8: Stimme völlig zu | CD8: Stimme nicht zu | CE8: Stimme nicht zu | CF8: Weder noch | CG8: Stimme nicht zu | CH8: Stimme zu | CI8: Stimme nicht zu | CJ8: Weder noch | CK8: Vollständig dominierend | CL8: Gar nicht | CM8: Gar nicht | CN8: Gar nicht | CO8: 421.76786 | CP8: 549.64682 | CQ8: 271.3762 | CR8: 0.55147287 | CS8: 0.011727555 | CT8: 0.022405787
A9: 8 | B9: German | C9: female | D9: 24 | E9: TE0+HF+6 | F9: 16.12.2025 | G9: 0.58518519 | H9: 0.58611111 | I9: 0.5875 | J9: 88.730912 | K9: 100.28499 | L9: 59.517762 | M9: 0.56280952 | N9: 0.013647109 | O9: 0.028022733 | P9: 0.58751157 | Q9: 0.58878472 | R9: 7 | S9: 6 | T9: 53.501623 | U9: 47.945713 | V9: 50.196904 | W9: 0.54142466 | X9: 0.011622687 | Y9: 0.021114465 | Z9: 0.58888889 | AA9: 0.59027778 | AB9: 54.346853 | AC9: 50.276199 | AD9: 58.73433 | AE9: 0.54872527 | AF9: 0.011905367 | AG9: 0.02263775 | AH9: 0.59028935 | AI9: 0.59146991 | AJ9: 6 | AK9: 6 | AL9: 50.584678 | AM9: 42.481737 | AN9: 50.94264 | AO9: 0.51349333 | AP9: 0.011365191 | AQ9: 0.020959293 | AR9: 0.59166667 | AS9: 0.59305556 | AT9: 70.521648 | AU9: 50.067284 | AV9: 60.657551 | AW9: 0.4452809 | AX9: 0.011401368 | AY9: 0.02118807 | AZ9: 0.59305556 | BA9: 0.59791667 | BB9: Durch die komplette Klanglandschaft | BC9: keine | BD9: Messungen an der Strehlener Strape und Radeberger Straße für ein Soundscape-Projekt, November, je eine halbe Stunde Aufnahmen | BE9: Nein | BF9: keine | BG9: Nein | BH9: keine | BI9: Ja | BJ9: Strehlener Straße, Radeberger Straße | BK9: Ja | BL9: Geräuschmessung | BM9: Ja | BN9: Messkopfhörer+Head Acoustics Gerät | BO9: Ja | BP9: November | BQ9: Ja | BR9: Kalt und laut | BS9: Ja | BT9: Schwer zu beschreiben, eine Mischung aus "will nach Hause (Abendaufnahme in der Radeberger Straße)" und "macht Spaß" | BU9: 70% | BV9: Genervt/Stört | BW9: Stimme überhaupt nicht zu | BX9: Stimme zu | BY9: Weder noch | BZ9: Stimme nicht zu | CA9: Stimme überhaupt nicht zu | CB9: Stimme völlig zu | CC9: Stimme zu | CD9: Weder noch | CE9: Stimme nicht zu | CF9: Stimme zu | CH9: Stimme überhaupt nicht zu | CI9: Stimme völlig zu | CJ9: Stimme zu | CK9: Stimme überhaupt nicht zu | CL9: Vollständig dominierend | CM9: Gar nicht | CN9: Gar nicht | CO9: 42.857211 | CP9: 44.473512 | CQ9: 208.63666 | CR9: 0.53359344 | CS9: 0.010276141 | CT9: 0.017743052
A10: 9 | B10: Brazilien | C10: male | D10: 32 | E10: TE0-10 | F10: 17.12.2025 | G10: 0.38465278 | H10: 0.38680556 | I10: 0.38819444 | J10: 146.20855 | K10: 190.62153 | L10: 60.017222 | M10: 0.55117778 | N10: 0.01117858 | O10: 0.020375354 | P10: 0.39208333 | Q10: 0.39336806 | R10: 8 | S10: 8 | T10: 37.427884 | U10: 53.667929 | V10: 54.938 | W10: 0.507625 | X10: 0.01069751 | Y10: 0.019655668 | Z10: 0.39337963 | AA10: 0.39462963 | AB10: 93.789412 | AC10: 120.9976 | AD10: 54.739443 | AE10: 0.48475949 | AF10: 0.011380588 | AG10: 0.021241582 | AH10: 0.3946412 | AI10: 0.39592593 | AJ10: 8 | AK10: 8 | AL10: 91.116985 | AM10: 121.443 | AN10: 56.699398 | AO10: 0.49004819 | AP10: 0.012025615 | AQ10: 0.022056146 | AR10: 0.39583333 | AS10: 0.39722222 | AT10: 102.09518 | AU10: 139.78058 | AV10: 52.758561 | AW10: 0.52136585 | AX10: 0.0092112221 | AY10: 0.017114284 | AZ10: 0.39722222 | BA10: 0.40138889 | BB10: Nein | BC10: keine | BD10: Nein | BE10: Nein | BF10: keine | BG10: Nein | BH10: keine | BI10: Nein | BJ10: keine | BK10: Ja | BL10: Caminhar na rua / walk on the street | BM10: Nein | BN10: keine | BO10: Nein | BP10: keine | BQ10: Nein | BR10: keine | BS10: Nein | BT10: keine | BU10: 90 | BV10: Tranquilidade / Calmness | BW10: Stimme zu | BX10: Stimme überhaupt nicht zu | BY10: Stimme zu | BZ10: Stimme zu | CA10: Stimme völlig zu | CB10: Stimme nicht zu | CC10: Stimme überhaupt nicht zu | CD10: Stimme zu | CE10: Stimme zu | CF10: Stimme überhaupt nicht zu | CH10: Stimme zu | CI10: Stimme nicht zu | CJ10: Stimme nicht zu | CK10: Stimme zu | CL10: Vollständig dominierend | CM10: Gar nicht | CN10: Ein wenig | CO10: 102.67307 | CP10: 133.06481 | CQ10: 181.80619 | CR10: 0.53673359 | CS10: 0.010044122 | CT10: 0.016893148
A11: 10 | B11: German | C11: male | D11: 31 | E11: TE0+SL+10 | F11: 17.12.2025 | G11: 0.44142361 | H11: 0.44722222 | I11: 0.44861111 | J11: 62.081739 | K11: 56.913419 | L11: 58.530429 | M11: 0.527 | N11: 0.0075966674 | O11: 0.017149349 | P11: 0.44862269 | Q11: 0.44958333 | R11: 6 | S11: 5 | T11: 47.89924 | U11: 41.337547 | V11: 40.452915 | W11: 0.55644068 | X11: 0.0082715626 | Y11: 0.025365502 | Z11: 0.44959491 | AA11: 0.45069444 | AB11: 469.55704 | AC11: 655.49879 | AD11: 48.405433 | AE11: 0.486 | AF11: 0.0073008443 | AG11: 0.023348396 | AH11: 0.45078704 | AI11: 0.45168981 | AJ11: 6 | AK11: 5 | AL11: 258.30185 | AM11: 326.86754 | AN11: 35.58275 | AO11: 0.65975 | AP11: 0.075613307 | AQ11: 0.14592173 | AR11: 0.45138889 | AS11: 0.45277778 | AT11: 82.245391 | AU11: 110.55811 | AV11: 46.417014 | AW11: 0.5333913 | AX11: 0.0096306746 | AY11: 0.041443629 | AZ11: 0.45277778 | BA11: 0.45555556 | BB11: Klanglandschaft | BC11: - | BD11: Ich erinnere mich zum Flohmarkt an der Elbe zu gehen | BE11: Nein | BF11: kein | BG11: Ja | BH11: Ein Freund | BI11: Ja | BJ11: Flohmarkt an Elbe | BK11: Ja | BL11: Auf Flohmarkt gehen | BM11: Ja | BN11: DDR Schallplatte | BO11: Ja | BP11: Herbst | BQ11: Nein | BR11: keine | BS11: Ja | BT11: Entspannt | BU11: 89% | BV11: Entspannung | BW11: Stimme zu | BX11: Stimme nicht zu | BY11: Stimme nicht zu | BZ11: Stimme zu | CA11: Stimme zu | CB11: Stimme überhaupt nicht zu | CC11: Stimme nicht zu | CD11: Stimme völlig zu | CE11: Stimme zu | CF11: Stimme nicht zu | CH11: Stimme zu | CI11: Stimme nicht zu | CJ11: Stimme nicht zu | CK11: Stimme zu | CL11: Stark | CM11: Mäßig | CN11: Ein wenig | CO11: 58.86646 | CP11: 48.215098 | CQ11: 121.867 | CR11: 0.55781818 | CS11: 0.013161301 | CT11: 0.025431658
A12: 11 | B12: Ucraine | C12: male | D12: 29 | E12: TE0+HF+6 | F12: 17.12.2025 | G12: 0.549375 | H12: 0.55416667 | I12: 0.55555556 | J12: 95.982435 | K12: 122.20569 | L12: 58.133448 | M12: 0.51383908 | N12: 0.0092462537 | O12: 0.023102987 | P12: 0.55556713 | Q12: 0.556875 | R12: 6 | S12: 5 | T12: 95.542726 | U12: 90.801878 | V12: 56.582317 | W12: 0.47170732 | X12: 0.010096111 | Y12: 0.024947705 | Z12: 0.55694444 | AA12: 0.55833333 | AB12: 492.76952 | AD12: 41.458097 | AE12: 0.5033871 | AF12: 0.010665255 | AG12: 0.028770201 | AH12: 0.55834491 | AI12: 0.55930556 | AJ12: 5 | AK12: 4 | AL12: 74.05919 | AM12: 666.99342 | AN12: 47.621412 | AO12: 0.51620588 | AP12: 0.0085482947 | AQ12: 0.025575822 | AR12: 0.55902778 | AS12: 0.56041667 | AT12: 56.868298 | AU12: 70.933935 | AV12: 239.13411 | AW12: 0.53866859 | AX12: 0.0089072575 | AY12: 0.017951624 | AZ12: 0.56041667 | BA12: 0.56597222 | BB12: Music soundss kind like typical LoFi mixtape | BC12: Masking music | BD12: Jus a picture of the animation girls which is doing their home work in a loop | BE12: No | BF12: None | BG12: Yes | BH12: "LoFi" girl. It is a common meme in the Internet | BI12: No | BJ12: None | BK12: No | BL12: None | BM12: No | BN12: None | BO12: Yes | BP12: Cozy evenings | BQ12: No | BR12: None | BS12: Yes | BT12: Pleasence | BU12: 50% | BV12: Yes, Pleasure | BW12: Strongly agree | BX12: Strongly disagree | BY12: Strongly agree | BZ12: Disagree | CA12: Strongly agree | CB12: Strongly disagree | CC12: Neither | CD12: Agree | CE12: Neither | CF12: Strongly disagree | CG12: Strongly agree | CH12: Agree | CI12: Disagree | CJ12: Strongly disagree | CK12: Strongly agree | CL12: A little | CM12: Not at all | CN12: Not at all | CO12: 50.587688 | CP12: 67.341562 | CQ12: 59.638391 | CR12: 0.47165517 | CS12: 0.010110255 | CT12: 0.024909402
A13: 12 | B13: China | C13: male | D13: 21 | E13: TE0 | F13: 17.12.2025 | G13: 0.6119213 | H13: 0.6125 | I13: 0.61388889 | J13: 61.295567 | K13: 72.9877 | L13: 60.423356 | M13: 0.49584444 | N13: 0.012477583 | O13: 0.033753018 | P13: 0.61390046 | Q13: 0.61444444 | R13: 3 | S13: 2 | T13: 689.14706 | U13: 707.90301 | V13: 23.360343 | W13: 0.45805714 | X13: 0.018095389 | Y13: 0.067008511 | Z13: 0.61458333 | AA13: 0.61597222 | AB13: 326.02341 | AC13: 457.16679 | AD13: 58.379244 | AE13: 0.44912195 | AF13: 0.018843732 | AG13: 0.051399581 | AH13: 0.61712963 | AI13: 0.61821759 | AJ13: 6 | AK13: 6 | AL13: 203.66637 | AM13: 186.71045 | AN13: 48.046781 | AO13: 0.49046875 | AP13: 0.020955462 | AQ13: 0.07300024 | AR13: 0.61805556 | AS13: 0.61944444 | AT13: 79.07268 | AU13: 17.242371 | AV13: 51.930468 | AW13: 0.45153247 | AX13: 0.017508414 | AY13: 0.061122486 | AZ13: 0.61944444 | BA13: 0.625 | BB13: no | BC13: none | BD13: Silently recite in one's mind | BE13: no | BF13: none | BG13: no | BH13: none | BI13: no | BJ13: none | BK13: no | BL13: none | BM13: no | BN13: none | BO13: no | BP13: none | BQ13: no | BR13: none | BS13: yes | BT13: nervous | BU13: 70 | BV13: peaceful | BW13: Agree | BX13: Neither | BY13: Disagree | BZ13: Agree | CA13: Agree | CB13: Neither | CC13: Disagree | CD13: Disagree | CE13: Agree | CF13: Disagree | CG13: Agree | CH13: Agree | CI13: Disagree | CJ13: Neither | CK13: Agree | CL13: Moderately | CM13: Not at all | CN13: Moderately | CO13: 161.56135 | CP13: 197.61685 | CQ13: 242.09793 | CR13: 0.52516923 | CS13: 0.01208686 | CT13: 0.026862907
A14: 13 | B14: China | C14: female | D14: 24 | E14: Te0-10 | F14: 18.12.2025 | G14: 0.4540162 | H14: 0.45416667 | I14: 0.45555556 | J14: 0 | L14: 662.32388 | M14: 0.52171723 | N14: 0.013284753 | O14: 0.023207747 | P14: 0.45556713 | Q14: 0.45658565 | R14: 7 | S14: 7 | T14: 511.82888 | U14: 518.03571 | V14: 43.527382 | W14: 0.52585294 | X14: 0.011391559 | Y14: 0.026479815 | Z14: 0.45659722 | AA14: 0.45797454 | AB14: 85.756046 | AC14: 28.221396 | AD14: 59.201489 | AE14: 0.50711111 | AF14: 0.010636856 | AG14: 0.023892531 | AH14: 0.45837963 | AI14: 0.45950231 | AJ14: 6 | AK14: 6 | AL14: 75.138956 | AM14: 30.159365 | AN14: 47.500543 | AO14: 0.49331429 | AP14: 0.010583043 | AQ14: 0.024663789 | AR14: 0.45972222 | AS14: 0.46111111 | AT14: 77.542598 | AU14: 71.809577 | AV14: 57.500711 | AW14: 0.53417778 | AX14: 0.010041834 | AY14: 0.022658033 | AZ14: 0.46111111 | BA14: 0.46805556 | BB14: yes,it is. | BC14: it reminds me of the busy traffic when I was in high school. | BD14: Every morning, mv father would drive me to school, and when the window was open, it sounded totally like that. | BE14: Yes | BF14: high schoool time reminds of the best age of me, which is innocent and beautiful, it feels like full of hope. | BG14: YES | BH14: my father,and all my classmates | BI14: yes | BJ14: the street to my high school | BK14: yes | BL14: attending class | BM14: yes | BN14: busy cars überall | BO14: yes | BP14: morning 6am to 8 am | BQ14: yes | BR14: busy nut intersting, bucause a new day gonna start | BS14: yes | BT14: hope! | BU14: 70 | BV14: yes,bright emotions. | BW14: Agree | BX14: Agree | BY14: Agree | BZ14: Neither | CA14: Disagree | CB14: Disagree | CC14: Neither | CD14: Agree | CE14: Strongly disagree | CF14: Neither | CG14: Neither | CH14: Neither | CI14: Agree | CJ14: Disagree | CK14: Neither | CL14: A lot | CM14: A little | CN14: Not at all | CO14: 59.953231 | CP14: 58.914205 | CQ14: 298.74301 | CR14: 0.53191975 | CS14: 0.014650259 | CT14: 0.023860975
A15: 14 | B15: France | C15: male | D15: 31 | E15: TE0+SL+10 | F15: 18.12.2025 | G15: 0.59328704 | H15: 0.59305556 | I15: 0.59444444 | J15: 139.05737 | K15: 126.47171 | L15: 52.709362 | M15: 0.56147826 | N15: 0.033144228 | O15: 0.056304299 | P15: 0.59445602 | Q15: 0.59565972 | R15: 7 | S15: 7 | T15: 87.299527 | U15: 85.870619 | V15: 50.249333 | W15: 0.51671795 | X15: 0.011729011 | Y15: 0.029301269 | Z15: 0.59583333 | AA15: 0.59722222 | AB15: 138.81868 | AC15: 125.78451 | AD15: 59.800523 | AE15: 0.51406818 | AF15: 0.011730483 | AG15: 0.027301901 | AH15: 0.5972338 | AI15: 0.59828704 | AJ15: 6 | AK15: 5 | AL15: 126.08697 | AM15: 143.17363 | AN15: 46.672647 | AO15: 0.509 | AP15: 0.011226017 | AQ15: 0.028007683 | AR15: 0.59791667 | AS15: 0.59930556 | AT15: 84.251298 | AU15: 78.056032 | AV15: 42.98225 | AW15: 0.4761875 | AX15: 0.010341687 | AY15: 0.02618674 | AZ15: 0.59930556 | BA15: 0.60208333 | BB15: no | BC15: none | BD15: none | BE15: no | BF15: none | BG15: none | BH15: none | BI15: no | BJ15: none | BK15: no | BL15: none | BM15: no | BN15: none | BO15: no | BP15: none | BQ15: no | BR15: none | BS15: no | BT15: none | BU15: 100 | BV15: none | BW15: Neither | BX15: Neither | BY15: Agree | BZ15: Disagree | CA15: Agree | CB15: Disagree | CC15: Agree | CD15: Disagree | CE15: Strongly disagree | CF15: Disagree | CG15: Neither | CH15: Agree | CI15: Agree | CJ15: Neither | CK15: Neither | CL15: A lot | CM15: Not at all | CN15: Not at all | CO15: 69.869549 | CP15: 62.136327 | CQ15: 118.10706 | CR15: 0.46564972 | CS15: 0.0089790097 | CT15: 0.019324403
A16: 15 | B16: China | C16: male | D16: 27 | E16: TE0+HF+6 | F16: 18.12.2025 | G16: 0.65177083 | H16: 0.65347222 | I16: 0.65486111 | J16: 54.111697 | K16: 44.05289 | L16: 60.410764 | M16: 0.50638202 | N16: 0.011863366 | O16: 0.03924332 | P16: 0.6550463 | Q16: 0.65631944 | R16: 7 | S16: 7 | T16: 95.051162 | U16: 43.312488 | V16: 54.274123 | W16: 0.5111358 | X16: 0.014837004 | Y16: 0.045323368 | Z16: 0.65633102 | AA16: 0.65770833 | AB16: 93.426125 | AC16: 64.01597 | AD16: 59.635195 | AE16: 0.56526437 | AF16: 0.011917082 | AG16: 0.038607169 | AH16: 0.65771991 | AI16: 0.65907407 | AJ16: 7 | AK16: 7 | AL16: 80.137478 | AM16: 43.059221 | AN16: 58.415465 | AO16: 0.4604186 | AP16: 0.014041934 | AQ16: 0.042519108 | AR16: 0.65902778 | AS16: 0.66041667 | AT16: 108.31609 | AU16: 55.935569 | AV16: 57.194753 | AW16: 0.50778824 | AX16: 0.013651923 | AY16: 0.041673233 | AZ16: 0.66041667 | BA16: 0.66527778 | BB16: no | BC16: none | BD16: peaceful forest | BE16: no | BF16: none | BG16: no | BH16: none | BI16: yes | BJ16: Dresden | BK16: yes | BL16: driving | BM16: yes | BN16: car | BO16: yes | BP16: morning | BQ16: yes | BR16: quiet | BS16: yes | BT16: peasedful | BU16: 10% | BV16: no | BW16: Agree | BX16: Strongly disagree | BY16: Strongly disagree | BZ16: Agree | CA16: Strongly agree | CB16: Strongly disagree | CC16: Disagree | CD16: Disagree | CE16: Strongly agree | CF16: Strongly disagree | CG16: Strongly agree | CH16: Strongly agree | CI16: Strongly disagree | CJ16: Strongly disagree | CK16: Agree | CL16: Moderately | CM16: Not at all | CN16: A little | CO16: 76.59003 | CP16: 68.328423 | CQ16: 198.66011 | CR16: 0.51236101 | CS16: 0.012465318 | CT16: 0.026907929
A17: 16 | B17: German | C17: female | D17: 63 | E17: TE0-10 | F17: 19.12.2025 | G17: 0.34951389 | H17: 0.34930556 | I17: 0.35069444 | J17: 54.990586 | K17: 49.808921 | L17: 51.262141 | M17: 0.46890141 | N17: 0.014058967 | O17: 0.042210856 | P17: 0.35070602 | Q17: 0.35186343 | R17: 6 | S17: 5 | T17: 42.192935 | U17: 57.011004 | V17: 51.074778 | W17: 0.51497222 | X17: 0.012705124 | Y17: 0.038846234 | Z17: 0.351875 | AA17: 0.35325231 | AB17: 47.291928 | AC17: 20.72208 | AD17: 58.963386 | AE17: 0.48272727 | AF17: 0.011797561 | AG17: 0.032964435 | AH17: 0.35326389 | AI17: 0.35393519 | AJ17: 5 | AK17: 4 | AL17: 44.834506 | AM17: 40.037104 | AN17: 28.296878 | AO17: 0.47146341 | AP17: 0.015142353 | AQ17: 0.052002757 | AR17: 0.35347222 | AS17: 0.35486111 | AT17: 65.429154 | AU17: 22.096802 | AV17: 60.163402 | AW17: 0.48951724 | AX17: 0.014258853 | AY17: 0.038384635 | AZ17: 0.35555556 | BA17: 0.36180556 | BB17: Landschaft | BC17: - | BD17: schöne Fahrt am Elbufer in Dresden mit dem Auto | BE17: ja | BF17: seltene schöne angenehme stressfreie Fahrt mit angenehmer Erinnerung | BG17: ja | BH17: meine Kinder | BI17: ja | BJ17: Elbufer in Dresden | BK17: ja | BL17: Fahrt mit Auto | BM17: ja | BN17: Auto | BO17: ja | BP17: abends | BQ17: ja | BR17: Gedenke: Wie schön ist Dresden! | BS17: ja | BT17: Angenehm | BU17: 70% | BV17: angenehm, beruhigend, gute Laune | BW17: Stimme völlig zu | BX17: Stimme überhaupt nicht zu | BY17: Stimme zu | BZ17: Stimme nicht zu | CA17: Stimme völlig zu | CB17: Stimme überhaupt nicht zu | CC17: Stimme zu | CD17: Weder noch | CE17: Stimme zu | CF17: Stimme überhaupt nicht zu | CH17: Stimme völlig zu | CI17: Stimme nicht zu | CJ17: Weder noch | CK17: Stimme völlig zu | CL17: Ein wenig | CM17: Stark | CN17: Gar nicht | CO17: 23.637601 | CP17: 20.465044 | CQ17: 271.399 | CR17: 0.50787879 | CS17: 0.008983638 | CT17: 0.018214293
A18: 17 | B18: India | C18: male | D18: 40 | E18: TE0+HF+6 | F18: 19.12.2025 | G18: 0.43765046 | H18: 0.43819444 | I18: 0.43958333 | J18: 378.97016 | K18: 650.32505 | L18: 57.753136 | M18: 0.54156818 | N18: 0.010456088 | O18: 0.024229404 | P18: 0.43959491 | Q18: 0.44069444 | R18: 6 | S18: 6 | T18: 437.41835 | U18: 486.81413 | V18: 46.139479 | W18: 0.48235616 | X18: 0.01014249 | Y18: 0.026456825 | Z18: 0.44097222 | AA18: 0.44236111 | AB18: 327.19992 | AC18: 450.91063 | AD18: 60.504067 | AE18: 0.51429213 | AF18: 0.0090628287 | AG18: 0.021967176 | AH18: 0.44237269 | AI18: 0.44357639 | AJ18: 6 | AK18: 5 | AL18: 389.61619 | AM18: 570.52202 | AN18: 60.243318 | AO18: 0.46470455 | AP18: 0.0094323482 | AQ18: 0.022534473 | AR18: 0.44375 | AS18: 0.44513889 | AT18: 528.77498 | AU18: 699.0217 | AV18: 60.618227 | AW18: 0.49886364 | AX18: 0.0073596236 | AY18: 0.018990318 | AZ18: 0.44513889 | BA18: 0.45277778 | BB18: Sound | BC18: Wind and running vehicle's sound. | BD18: It trigeer my driving experience. I can hear the same sounds whiloe driving. | BE18: Yes | BF18: These sounds are a part of my daily life. | BG18: No | BH18: none | BI18: Yes | BJ18: The sounds are from the same place where all the vehicles are passing through. | BK18: Yes | BL18: Driving | BM18: Yes | BN18: Cars | BO18: Yes | BP18: It may be afternoon | BQ18: No | BR18: none | BS18: No | BT18: none | BU18: 90 | BV18: no | BW18: Disagree | BX18: Neither | BY18: Disagree | BZ18: Agree | CA18: Disagree | CB18: Disagree | CC18: Disagree | CD18: Disagree | CE18: Disagree | CF18: Neither | CG18: Disagree | CH18: Disagree | CI18: Agree | CJ18: Neither | CK18: Neither | CL18: Moderately | CM18: A little | CN18: A lot | CO18: 386.85349 | CP18: 565.77537 | CQ18: 330.20027 | CR18: 0.50916102 | CS18: 0.0084679717 | CT18: 0.015825458
A19: 18 | B19: China | C19: male | D19: 25 | E19: TE0 | F19: 19.12.2025 | G19: 0.57206019 | H19: 0.57152778 | I19: 0.57291667 | J19: 0 | L19: 36.966604 | M19: 0.60018868 | N19: 0.01019217 | O19: 0.020062579 | P19: 0.57292824 | Q19: 0.57341435 | R19: 3 | S19: 2 | T19: 618.83762 | U19: 1015.7191 | V19: 20.3702 | W19: 0.5346 | X19: 0.010673475 | Y19: 0.025290355 | Z19: 0.57361111 | AA19: 0.575 | AB19: 346.63917 | AC19: 455.0457 | AD19: 58.639191 | AE19: 0.51898876 | AF19: 0.010423148 | AG19: 0.020408637 | AH19: 0.57517361 | AI19: 0.57646991 | AJ19: 7 | AK19: 7 | AL19: 182.60523 | AM19: 255.1797 | AN19: 55.003071 | AO19: 0.58011905 | AP19: 0.010529822 | AQ19: 0.021413099 | AR19: 0.57638889 | AS19: 0.57777778 | AT19: 389.93455 | AU19: 422.25821 | AV19: 55.543452 | AW19: 0.53604762 | AX19: 0.012284846 | AY19: 0.024894989 | AZ19: 0.57777778 | BA19: 0.58472222 | BB19: Soundscape | BC19: - | BD19: like when I about to cross the street | BE19: no | BF19: none | BG19: no | BH19: none | BI19: Yes | BJ19: like when i cross the street to play basketball at my home | BK19: yes | BL19: playing basketball | BM19: yes | BN19: basketball | BO19: no | BP19: no | BQ19: yes | BR19: more or less like what kind of training i need to do in the basketball court | BS19: yes | BT19: mostly relaxed | BU19: 40 | BV19: not really, maybe abit homesick | BW19: Neither | BX19: Agree | BY19: Neither | BZ19: Neither | CA19: Disagree | CB19: Agree | CC19: Neither | CD19: Neither | CE19: Strongly disagree | CF19: Neither | CG19: Neither | CH19: Neither | CI19: Agree | CJ19: Neither | CK19: Disagree | CL19: Dominates completely | CM19: Not at all | CN19: A little | CO19: 260.15676 | CP19: 358.45518 | CQ19: 299.28628 | CR19: 0.48286897 | CS19: 0.0094848332 | CT19: 0.016767805
A20: 19 | B20: Singapore | C20: male | D20: 19 | E20: TE0+SL+10 | F20: 19.12.2025 | G20: 0.64271991 | H20: 0.64236111 | I20: 0.64375 | J20: 408.92773 | K20: 541.20542 | L20: 44.186281 | M20: 0.4810625 | N20: 0.017704922 | O20: 0.045801569 | P20: 0.64391204 | Q20: 0.64517361 | R20: 7 | S20: 6 | T20: 72.812415 | U20: 55.721635 | V20: 55.640727 | W20: 0.50592208 | X20: 0.012794281 | Y20: 0.036739828 | Z20: 0.64518519 | AA20: 0.6465625 | AB20: 118.29955 | AC20: 125.36163 | AD20: 59.555906 | AE20: 0.54312941 | AF20: 0.014739848 | AG20: 0.037532223 | AH20: 0.64666667 | AI20: 0.64715278 | AJ20: 4 | AK20: 3 | AL20: 605.39838 | AM20: 569.70694 | AN20: 20.702 | AO20: 0.5302 | AP20: 0.019544233 | AQ20: 0.075362092 | AR20: 0.64722222 | AS20: 0.64861111 | AT20: 88.398699 | AU20: 89.194646 | AV20: 59.959908 | AW20: 0.5285977 | AX20: 0.014982409 | AY20: 0.039478637 | AZ20: 0.65347222 | BA20: 0.65763889 | BB20: no | BC20: no | BD20: I was not focusing on the video or sound instead I focus more on trying to remember the number but at a certain point its just get hard to remember as the number is getting more and more | BE20: yes | BF20: I think its very interesting as it is trying to test my memory | BG20: no | BH20: no | BI20: no | BJ20: no | BK20: no | BL20: no | BM20: noi | BN20: no | BO20: no | BP20: no | BQ20: no | BR20: no | BS20: no | BT20: no | BU20: 80 | BV20: no | BW20: Neither | BX20: Neither | BY20: Neither | BZ20: Neither | CA20: Agree | CB20: Disagree | CC20: Neither | CD20: Agree | CE20: Disagree | CF20: Neither | CG20: Neither | CH20: Agree | CI20: Disagree | CJ20: Disagree | CK20: Neither | CL20: Moderately | CM20: Not at all | CN20: Not at all | CO20: 90.947752 | CP20: 111.83406 | CQ20: 177.97811 | CR20: 0.516583 | CS20: 0.012012701 | CT20: 0.025616455
A21: 20 | B21: China | C21: male | D21: 23 | E21: TE0-10 | F21: 06.01.2026 | G21: 0.5500463 | H21: 0.55 | I21: 0.55138889 | J21: 69.633047 | L21: 52.071593 | M21: 0.51718644 | N21: 0.025446171 | O21: 0.090734585 | P21: 0.55140046 | Q21: 0.5525 | R21: 6 | S21: 6 | T21: 31.748965 | U21: 17.894133 | V21: 45.076 | W21: 0.46807143 | X21: 0.020191376 | Y21: 0.084705176 | Z21: 0.55277778 | AA21: 0.55416667 | AB21: 81.456078 | AC21: 76.091164 | AD21: 57.441944 | AE21: 0.42466667 | AF21: 0.020340098 | AG21: 0.073303923 | AH21: 0.55434028 | AI21: 0.55563657 | AJ21: 7 | AK21: 7 | AL21: 89.689895 | AM21: 104.48616 | AN21: 51.562837 | AO21: 0.45976744 | AP21: 0.035880088 | AQ21: 0.12902677 | AR21: 0.55555556 | AS21: 0.55694444 | AT21: 59.518392 | AU21: 68.37057 | AV21: 49.452633 | AW21: 0.4825 | AX21: 0.021784478 | AY21: 0.085931764 | AZ21: 0.55694444 | BA21: 0.5625 | BB21: soundscape | BC21: No | BD21: No | BE21: No | BF21: No | BG21: No | BH21: No | BI21: No | BJ21: No | BK21: No | BL21: No | BM21: No | BN21: No | BO21: No | BP21: No | BQ21: No | BR21: No | BS21: No | BT21: No | BU21: 80% | BV21: a little bit annoying | BW21: Strongly disagree | BX21: Agree | BY21: Disagree | BZ21: Disagree | CA21: Strongly disagree | CB21: Agree | CC21: Agree | CD21: Strongly agree | CE21: Strongly disagree | CF21: Agree | CG21: Disagree | CH21: Strongly agree | CI21: Agree | CJ21: Neither | CK21: Disagree | CL21: A lot | CM21: Not at all | CN21: A little | CO21: 117.51266 | CP21: 157.41709 | CQ21: 222.94763 | CR21: 0.58472539 | CS21: 0.027823753 | CT21: 0.072024976
A22: 21 | B22: China | C22: male | D22: 23 | E22: TE0 | F22: 07.01.2026 | G22: 0.41842593 | H22: 0.41805556 | I22: 0.41944444 | J22: 421.9149 | K22: 610.71067 | L22: 43.20503 | M22: 0.48121212 | N22: 0.013535781 | O22: 0.031431934 | P22: 0.41988426 | Q22: 0.42114583 | R22: 8 | S22: 8 | T22: 111.94031 | U22: 118.16959 | V22: 54.472582 | W22: 0.50635443 | X22: 0.012567983 | Y22: 0.027265328 | Z22: 0.42115741 | AA22: 0.42253472 | AB22: 86.481867 | AC22: 72.50541 | AD22: 60.868 | AE22: 0.46444944 | AF22: 0.011660738 | AG22: 0.025244534 | AH22: 0.42396991 | AI22: 0.42515046 | AJ22: 7 | AK22: 7 | AL22: 352.49218 | AM22: 443.79513 | AN22: 49.356274 | AO22: 0.6310411 | AP22: 0.014668065 | AQ22: 0.037050114 | AR22: 0.425 | AS22: 0.42638889 | AT22: 135.96506 | AU22: 117.57078 | AV22: 52.804104 | AW22: 0.51657143 | AX22: 0.013247629 | AY22: 0.038484062 | AZ22: 0.42638889 | BA22: 0.43263889 | BB22: nein | BC22: nein | BD22: nein | BE22: nein | BF22: keine | BG22: ja | BH22: man auf der strasse | BI22: nein | BJ22: keine | BK22: ja | BL22: gehen zur universität | BM22: nein | BN22: keine | BO22: ja | BP22: morgen oder abend | BQ22: nein | BR22: keine | BS22: ja | BT22: nervous | BU22: 90 | BV22: nervous | BW22: Stimme überhaupt nicht zu | BX22: Weder noch | BY22: Stimme zu | BZ22: Stimme nicht zu | CA22: Stimme überhaupt nicht zu | CB22: Stimme völlig zu | CC22: Stimme zu | CD22: Stimme nicht zu | CE22: Stimme nicht zu | CF22: Stimme zu | CH22: Weder noch | CI22: Stimme zu | CJ22: Stimme zu | CK22: Stimme nicht zu | CL22: Stark | CM22: Ein wenig | CN22: Gar nicht | CO22: 83.791024 | CP22: 97.92762 | CQ22: 269.52745 | CR22: 0.51584264 | CS22: 0.011485169 | CT22: 0.022519831
A23: 22 | B23: China | C23: female | D23: 25 | E23: TE0+HF+6 | F23: 07.01.2027 | G23: 0.63670139 | H23: 0.63680556 | I23: 0.63819444 | J23: 93.682252 | K23: 113.88262 | L23: 60.224348 | M23: 0.50143478 | N23: 0.013657036 | O23: 0.026105501 | P23: 0.63836806 | Q23: 0.63961806 | R23: 8 | S23: 8 | T23: 47.79923 | U23: 47.041806 | V23: 53.247086 | W23: 0.47004938 | X23: 0.015552233 | Y23: 0.026521528 | Z23: 0.63962963 | AA23: 0.64100694 | AB23: 74.45479 | AC23: 72.628188 | AD23: 61.061724 | AE23: 0.45931034 | AF23: 0.014276309 | AG23: 0.023534321 | AH23: 0.64101852 | AI23: 0.64165509 | AJ23: 5 | AK23: 4 | AL23: 321.02036 | AM23: 481.04068 | AN23: 26.414488 | AO23: 0.53317073 | AP23: 0.015493464 | AQ23: 0.030081663 | AR23: 0.64166667 | AS23: 0.64305556 | AT23: 91.452746 | AU23: 107.1015 | AV23: 60.1304 | AW23: 0.51568889 | AX23: 0.012578211 | AY23: 0.022965029 | AZ23: 0.64305556 | BA23: 0.66041667 | BB23: Geräusch | BC23: Ich stand auf ein Fußgängerüberführung in Peking | BD23: Ich guckte nach unten, da fahrten viele Autos hin und her. Es war im Winter und der Wind war laut. Auch viele Leute lauften hinter mir. Rund um Fußgängerüberführung standen viele hohe Gebäude. | BE23: Nein | BF23: keine | BG23: Nein | BH23: keine | BI23: Ja | BJ23: Die Straße vor der Bibliothek SLUB | BK23: Ja | BL23: Winterspaziergang in Berlin | BM23: Ja | BN23: Ein Glaskugel | BO23: Ja | BP23: Oktober und November | BQ23: Ja | BR23: Ob das Leben zirkulär oder linear läuft | BS23: Ja | BT23: ruhe, gelassen | BU23: 70% | BV23: Ja. Melancholie | BW23: Weder noch | BX23: Weder noch | BY23: Stimme nicht zu | BZ23: Stimme nicht zu | CA23: Stimme nicht zu | CB23: Stimme zu | CC23: Stimme zu | CD23: Stimme zu | CE23: Stimme überhaupt nicht zu | CF23: Stimme zu | CH23: Stimme nicht zu | CI23: Stimme zu | CJ23: Stimme zu | CK23: Stimme nicht zu | CL23: Stark | CM23: Mäßig | CN23: Ein wenig | CO23: 220.15426 | CP23: 157.5997 | CQ23: 749.24445 | CR23: 0.53037547 | CS23: 0.013995342 | CT23: 0.02274451
A24: 23 | B24: China | C24: male | D24: 25 | E24: TE0-10 | F24: 08.01.2026 | G24: 0.58777778 | H24: 0.5875 | I24: 0.58888889 | J24: 27.907432 | K24: 14.90724 | L24: 46.991086 | M24: 0.48117143 | N24: 0.018584538 | O24: 0.045992572 | P24: 0.58917824 | Q24: 0.59041667 | R24: 7 | S24: 7 | T24: 31.867769 | U24: 20.4012 | V24: 52.397282 | W24: 0.5135641 | X24: 0.017272415 | Y24: 0.040729672 | Z24: 0.59041667 | AA24: 0.59180556 | AB24: 49.834608 | AC24: 59.166626 | AD24: 58.357576 | AE24: 0.50910588 | AF24: 0.015305189 | AG24: 0.03574418 | AH24: 0.59181713 | AI24: 0.59293981 | AJ24: 6 | AK24: 5 | AL24: 35.348119 | AM24: 26.019886 | AN24: 48.35371 | AO24: 0.51797101 | AP24: 0.016824906 | AQ24: 0.042316796 | AR24: 0.59236111 | AS24: 0.59375 | AT24: 45.962145 | AU24: 39.076847 | AV24: 34.368122 | AW24: 0.46277551 | AX24: 0.019296209 | AY24: 0.052978676 | AZ24: 0.59375 | BA24: 0.59930556 | BB24: No | BC24: No | BD24: No | BE24: No | BF24: No | BG24: No | BH24: No | BI24: No | BJ24: No | BK24: No | BL24: No | BM24: No | BN24: No | BO24: No | BP24: No | BQ24: Yes | BR24: like i am studying in my high school | BS24: Yes | BT24: chill feeling | BU24: 60 | BV24: yes, i feel relaxed | BW24: Agree | BX24: Strongly disagree | BY24: Agree | BZ24: Strongly agree | CA24: Strongly agree | CB24: Strongly disagree | CC24: Strongly disagree | CD24: Strongly disagree | CE24: Neither | CF24: Strongly disagree | CG24: Agree | CH24: Agree | CI24: Strongly disagree | CJ24: Strongly disagree | CK24: Agree | CL24: Not at all | CM24: Moderately | CN24: Not at all | CO24: 43.642797 | CP24: 47.437773 | CQ24: 234.62005 | CR24: 0.54773115 | CS24: 0.023082582 | CT24: 0.041342915
A25: 24 | B25: China | C25: male | D25: 27 | E25: TE0 | F25: 08.01.2027 | G25: 0.73119213 | H25: 0.73125 | I25: 0.73263889 | J25: 127.39612 | K25: 178.73703 | L25: 62.339231 | M25: 0.48874725 | N25: 0.014187757 | O25: 0.02614585 | P25: 0.73545139 | Q25: 0.73659722 | R25: 7 | S25: 7 | T25: 112.43668 | U25: 183.36942 | V25: 48.741413 | W25: 0.50432 | X25: 0.012082803 | Y25: 0.023901626 | Z25: 0.73659722 | AA25: 0.73798611 | AB25: 107.5331 | AC25: 141.54644 | AD25: 59.691701 | AE25: 0.42905747 | AF25: 0.012072084 | AG25: 0.023317592 | AH25: 0.73799769 | AI25: 0.7390162 | AJ25: 6 | AK25: 6 | AL25: 0 | AN25: 43.238812 | AO25: 0.53621875 | AP25: 0.013127191 | AQ25: 0.026163799 | AR25: 0.73888889 | AS25: 0.74027778 | AT25: 126.61971 | AU25: 178.20537 | AV25: 54.545575 | AW25: 0.52995 | AX25: 0.012118975 | AY25: 0.023567058 | AZ25: 0.74027778 | BA25: 0.74791667 | BB25: nein | BC25: nein | BD25: nein | BE25: Ja | BF25: wenn ich auf den Straße stehe | BG25: nein | BH25: keine | BI25: Nein | BJ25: keine | BK25: Nein | BL25: keine | BM25: Ja | BN25: Auto | BO25: Nein | BP25: Keine | BQ25: Nein | BR25: keine | BS25: Ja | BT25: Entspannend im Ferien | BU25: 95% | BV25: Ja,entspannend | BW25: Stimme zu | BX25: Stimme nicht zu | BY25: Stimme zu | BZ25: Weder noch | CA25: Weder noch | CB25: Stimme nicht zu | CC25: Weder noch | CD25: Stimme zu | CE25: Stimme nicht zu | CF25: Stimme nicht zu | CH25: Stimme zu | CI25: Stimme zu | CJ25: Weder noch | CK25: Stimme zu | CL25: Stark | CM25: Gar nicht | CN25: Ein wenig | CO25: 313.33754 | CP25: 417.5169 | CQ25: 333.44239 | CR25: 0.48533051 | CS25: 0.014782487 | CT25: 0.023458307
A26: 25 | B26: Taiwan | C26: female | D26: 30 | E26: TE0+HF+6 | F26: 09.01.2026 | G26: 0.4394213 | H26: 0.43958333 | I26: 0.44097222 | J26: 234.89769 | K26: 329.87825 | L26: 59.85608 | M26: 0.45992 | N26: 0.024013931 | O26: 0.064246801 | P26: 0.44097222 | Q26: 0.44210648 | R26: 6 | S26: 5 | T26: 177.59512 | U26: 254.14303 | V26: 49.790059 | W26: 0.45070588 | X26: 0.020150059 | Y26: 0.05415125 | Z26: 0.44210648 | AA26: 0.44349537 | AB26: 111.59514 | AC26: 141.47019 | AD26: 58.973692 | AE26: 0.48382418 | AF26: 0.013685099 | AG26: 0.039394885 | AH26: 0.44363426 | AI26: 0.44479167 | AJ26: 6 | AK26: 6 | AL26: 94.686906 | AM26: 103.68856 | AN26: 49.441342 | AO26: 0.50827397 | AP26: 0.013815792 | AQ26: 0.040475045 | AR26: 0.44444444 | AS26: 0.44583333 | AT26: 480.83261 | AU26: 680 | AV26: 42.978676 | AW26: 0.54241176 | AX26: 0.013694321 | AY26: 0.041240878 | AZ26: 0.44583333 | BA26: 0.45277778 | BB26: Geraüsch | BC26: leer lassen | BD26: wie zu Hause | BE26: Nein | BF26: keine | BG26: Nein | BH26: keine | BI26: Ja | BJ26: in unterwegs | BK26: Nein | BL26: keine | BM26: Nein | BN26: keine | BO26: ja | BP26: An Mongens | BQ26: Nein | BR26: keine | BS26: Ja | BT26: Rühig | BU26: 90% | BV26: Nien | BW26: Stimme zu | BX26: Stimme zu | BY26: Stimme völlig zu | BZ26: Weder noch | CA26: Stimme völlig zu | CB26: Weder noch | CC26: Weder noch | CD26: Weder noch | CE26: Weder noch | CF26: Stimme zu | CH26: Stimme nicht zu | CI26: Stimme nicht zu | CJ26: Stimme überhaupt nicht zu | CK26: Stimme völlig zu | CL26: Gar nicht | CM26: Mäßig | CN26: Vollständig dominierend | CO26: 414.25839 | CP26: 567.12013 | CQ26: 297.29417 | CR26: 0.46648677 | CS26: 0.019794224 | CT26: 0.038059217

Sheet S2 Datalog + Results
A1: ID | B1: Nationality | C1: Gender | D1: Age | E1: Audio file | F1: Date | G1: Start Physiological recording | H1: #1 Start 1.Baseline S2 | I1: #2 End 1.Baseline S2 | J1: #1 ECG - SDNN | K1: ECG - RMSSD | L1: #2 EDA - SCR onset | M1: # 3 EDA - SCR latency or rise time | N1: #4 EDA - SCR peak amplitude | O1: # 5 EDA - SCR peak prominence | P1: Start DSP FW S2 | Q1: End DSP FW S2 | R1: Trials DSP FW | S1: Correct trials DSP FW | T1: #6 ECG - SDNN | U1: ECG - RMSSD | V1: #7 EDA - SCR onset | W1: # 8 EDA - SCR latency or rise time | X1: #9 EDA - SCR peak amplitude | Y1: # 10 EDA - SCR peak prominence | Z1: #3 Start 2.Baseline S2 | AA1: #4 End 2. Baseline S2 | AB1: #11 ECG - SDNN | AC1: ECG - RMSSD | AD1: #12 EDA - SCR onset | AE1: # 13 EDA - SCR latency or rise time | AF1: #14 EDA - SCR peak amplitude | AG1: # 15 EDA - SCR peak prominence | AH1: Start DSP BW S2 | AI1: End DSP BW S2 | AJ1: Trials DSP BW | AK1: Correct trials DSP BW | AL1: #16 ECG - SDNN | AM1: ECG - RMSSD | AN1: #17 EDA - SCR onset | AO1: # 18 EDA - SCR latency or rise time | AP1: #19 EDA - SCR peak amplitude | AQ1: # 20 EDA - SCR peak prominence | AR1: #5 Start 3. Baseline S2 | AS1: #6 End 3. Baseline S2 | AT1: #21 ECG - SDNN | AU1: ECG - RMSSD | AV1: #22 EDA - SCR onset | AW1: # 23 EDA - SCR latency or rise time | AX1: #24 EDA - SCR peak amplitude | AY1: # 25 EDA - SCR peak prominence | AZ1: Start Memo S2 | BA1: End Memo S2 | BB1: AIsYourMemoryTriggeredByASpecificSoundOrOverallSoundscapeSoundS | BC1: IfSoundPleaseSpecifyleaveBlankIfNotApplicable | BD1: BDescribeYourMemoryInAsMuchDetailAsPossible | BE1: CIsThisAMeaningfulEventYesNo | BF1: IfYesSpecifyOtherwiseWriteNone | BG1: DIsThisConnectedToAPersonYesNo | BH1: IfYesSpecifyOtherwiseWriteNone_1 | BI1: EIsThisAssociatedWithAPlaceYesNo | BJ1: IfYesSpecifyOtherwiseWriteNone_2 | BK1: FIsThisLinkedToAnActivityYesNo | BL1: IfYesSpecifyOtherwiseWriteNone_3 | BM1: GIsThisAssociatedWithAnObjectYesNo | BN1: IfYesSpecifyOtherwiseWriteNone_4 | BO1: HIsThisConnectedToASpecificTimeYesNo | BP1: IfYesSpecifyOtherwiseWriteNone_5 | BQ1: IIsThisAssociatedWithAThoughtYesNo | BR1: IfYesSpecifyOtherwiseWriteNone_6 | BS1: JIsThisConnectedToAnEmotionYesNo | BT1: IfYesSpecifyOtherwiseWriteNone_7 | BU1: ToWhatExtentIsThePresentSoundEnvironmentAppropriateToThePlacePl | BV1: DoesTheSoundscapeEvokeAnyEmotionsIfYesWhichOnes | BW1: Agreement_PLEASANT | BX1: Agreement_CHAOTIC | BY1: Agreement_VIBRANT | BZ1: Agreement_UNEVENTFUL | CA1: Agreement_CALM | CB1: Agreement_ANNOYING | CC1: Agreement_EVENTFUL | CD1: Agreement_MONOTONOUS | CE1: Agreement_QUIET | CF1: Agreement_UNCOMFORTABLE | CG1: Agreement_COMFORTABLE | CH1: Agreement_NOTANNOYING | CI1: Agreement_NOISY | CJ1: Agreement_EXHAUSTING | CK1: Agreement_RELAXING | CL1: Intensity_MechanicalSounds | CM1: Intensity_HumanSounds | CN1: Intensity_NaturalSounds | CO1: #26 ECG - SDNN | CP1: ECG - RMSSD | CQ1: #27 EDA - SCR onset | CR1: # 28 EDA - SCR latency or rise time | CS1: #29 EDA - SCR peak amplitude | CT1: # 30 EDA - SCR peak prominence
A2: 1 | B2: Turkey | C2: male | D2: 36 | E2: TE0-10 | F2: 11.12.2025 | G2: 0.59134259 | H2: 0.60972222 | I2: 0.61111111 | J2: 147.93733 | K2: 200.66129 | L2: 59.441822 | M2: 0.52933333 | N2: 0.0077225964 | O2: 0.017420165 | P2: 0.61180556 | Q2: 0.61270833 | R2: 6 | S2: 6 | T2: 261.92319 | U2: 370.21375 | V2: 37.600806 | W2: 0.53574194 | X2: 0.0072646996 | Y2: 0.017733377 | Z2: 0.61271991 | AA2: 0.61388889 | AB2: 70.262611 | AC2: 79.126805 | AD2: 58.742048 | AE2: 0.53780723 | AF2: 0.0074955538 | AG2: 0.018533473 | AH2: 0.61417824 | AI2: 0.61556713 | AJ2: 7 | AK2: 7 | AL2: 82.991172 | AM2: 96.205885 | AN2: 58.397 | AO2: 0.56107317 | AP2: 0.0093612009 | AQ2: 0.022988518 | AR2: 0.61597222 | AS2: 0.61736111 | AT2: 242.08236 | AU2: 284.01268 | AV2: 61.115475 | AW2: 0.52215 | AX2: 0.010447813 | AY2: 0.025756345 | AZ2: 0.61736111 | BA2: 0.62083333 | BB2: NA | BC2: NA | BD2: NA | BE2: NA | BF2: NA | BG2: NA | BH2: NA | BI2: NA | BJ2: NA | BK2: NA | BL2: NA | BM2: NA | BN2: NA | BO2: NA | BP2: NA | BQ2: NA | BR2: NA | BS2: NA | BT2: NA | BU2: NA | BV2: NA | BW2: NA | BX2: NA | BY2: NA | BZ2: NA | CA2: NA | CB2: NA | CC2: NA | CD2: NA | CE2: NA | CF2: NA | CG2: NA | CH2: NA | CI2: NA | CJ2: NA | CK2: NA | CL2: NA | CM2: NA | CN2: NA | CO2: 122.17601 | CP2: 171.0452 | CQ2: 148.65485 | CR2: 0.54450926 | CS2: 0.0063667005 | CT2: 0.013953765
A3: 2 | B3: China | C3: male | D3: 24 | E3: TE0+Sim+10 | F3: 12.12.2025 | G3: 0.44652778 | H3: 0.46041667 | I3: 0.46180556 | J3: 134.58118 | K3: 127.46237 | L3: 59.790068 | M3: 0.53027273 | N3: 0.0071368789 | O3: 0.015277824 | P3: 0.46265046 | Q3: 0.46375 | R3: 7 | S3: 7 | T3: 184.71309 | U3: 164.88887 | V3: 81.583365 | W3: 0.4688254 | X3: 0.0070572413 | Y3: 0.01398159 | Z3: 0.46388889 | AA3: 0.46527778 | AB3: 111.59994 | AC3: 88.562302 | AD3: 60.129884 | AE3: 0.45488372 | AF3: 0.0076806238 | AG3: 0.016850844 | AH3: 0.46528935 | AI3: 0.46637731 | AJ3: 6 | AK3: 6 | AL3: 124.95847 | AM3: 54.753799 | AN3: 45.697808 | AO3: 0.52868493 | AP3: 0.0080011158 | AQ3: 0.018880168 | AR3: 0.46666667 | AS3: 0.46805556 | AT3: 178.81588 | AU3: 132.39301 | AV3: 60.499146 | AW3: 0.47986517 | AX3: 0.0076933201 | AY3: 0.017074239 | AZ3: 0.46805556 | BA3: 0.47291667 | BB3: yes | BC3: less nervous | BD3: the noise makes me nervous | BE3: yes | BF3: i don't know | BG3: no | BH3: none | BI3: yes | BJ3: road | BK3: no | BL3: none | BM3: yes | BN3: car | BO3: yes | BP3: walking on the street | BQ3: no | BR3: none | BS3: yes | BT3: uncomfortable | BU3: 80% | BV3: yes annoyed | BW3: Disagree | BX3: Agree | BY3: Disagree | BZ3: Agree | CA3: Strongly disagree | CB3: Agree | CC3: Disagree | CD3: Disagree | CE3: Strongly disagree | CF3: Agree | CG3: Disagree | CH3: Disagree | CI3: Strongly agree | CJ3: Strongly disagree | CK3: Strongly disagree | CL3: Dominates completely | CM3: Not at all | CN3: A little | CO3: 120.11268 | CP3: 109.79692 | CQ3: 208.71599 | CR3: 0.48572638 | CS3: 0.0072828545 | CT3: 0.013451806
A4: 3 | B4: Singapore | C4: male | D4: 21 | E4: TE0+HF+6 | F4: 12.12.2025 | G4: 0.56918981 | H4: 0.58263889 | I4: 0.59097222 | J4: 399.31765 | K4: 534.7963 | L4: 360.74862 | M4: 0.50651613 | N4: 0.0065484379 | O4: 0.011662402 | P4: 0.59207176 | Q4: 0.59319444 | R4: 7 | S4: 7 | T4: 291.00161 | U4: 434.48808 | V4: 49.037352 | W4: 0.47738028 | X4: 0.0074712633 | Y4: 0.019127876 | Z4: 0.59320602 | AA4: 0.59458333 | AB4: 217.84454 | AC4: 274.00254 | AD4: 57.940773 | AE4: 0.59175 | AF4: 0.0083586693 | AG4: 0.019459388 | AH4: 0.59459491 | AI4: 0.59461806 | AJ4: 1 | AK4: 0 | AL4: 0 | AN4: 0 | AO4: 0 | AP4: 0 | AQ4: 0 | AR4: 0.59462963 | AS4: 0.59600694 | AT4: 82.104262 | AU4: 79.503607 | AV4: 59.150761 | AW4: 0.49506522 | AX4: 0.0079302976 | AY4: 0.018997364 | AZ4: 0.59583333 | BA4: 0.59861111 | BB4: yes | BC4: like classical music | BD4: i went to a classical music concert it sounded similar | BE4: no | BF4: none | BG4: no | BH4: none | BI4: yes | BJ4: a concert | BK4: yes | BL4: music performance | BM4: no | BN4: none | BO4: no | BP4: none | BQ4: no | BR4: none | BS4: no | BT4: none | BU4: 30 | BV4: no | BW4: Agree | BX4: Neither | BY4: Neither | BZ4: Disagree | CA4: Agree | CB4: Disagree | CC4: Neither | CD4: Neither | CE4: Disagree | CF4: Neither | CG4: Agree | CH4: Agree | CI4: Neither | CJ4: Neither | CK4: Neither | CL4: Moderately | CM4: A little | CN4: A little | CO4: 399.06317 | CP4: 517.69854 | CQ4: 111.41472 | CR4: 0.51445399 | CS4: 0.0075049365 | CT4: 0.01603621
A5: 4 | B5: China | C5: female | D5: 28 | E5: TE0-10 | F5: 15.12.2025 | G5: 0.46399306 | H5: 0.47777778 | I5: 0.47916667 | J5: 101.3302 | K5: 121.038 | L5: 57.852228 | M5: 0.5364557 | N5: 0.018817436 | O5: 0.051954867 | P5: 0.47938657 | Q5: 0.48068287 | R5: 8 | S5: 8 | T5: 104.3179 | U5: 120.97006 | V5: 57.237013 | W5: 0.55488608 | X5: 0.016915622 | Y5: 0.049337597 | Z5: 0.48069444 | AA5: 0.48207176 | AB5: 167.20132 | AC5: 243.46598 | AD5: 60.515636 | AE5: 0.50968831 | AF5: 0.016865479 | AG5: 0.050305167 | AH5: 0.48326389 | AI5: 0.48428241 | AJ5: 7 | AK5: 6 | AN5: 44.826452 | AO5: 0.54287097 | AP5: 0.017381734 | AQ5: 0.05721839 | AR5: 0.48429398 | AS5: 0.4856713 | AT5: 192.87645 | AU5: 259.96164 | AV5: 58.830769 | AW5: 0.50138462 | AX5: 0.014893769 | AY5: 0.047317433 | AZ5: 0.48541667 | BA5: 0.48888889 | BB5: Soundscape | BC5: None | BD5: I feel it better. | BE5: No | BF5: None | BG5: No | BH5: None | BI5: No | BJ5: None | BK5: Yes | BL5: Historical Event | BM5: No | BN5: None | BO5: Yes | BP5: Some meaningful years | BQ5: No | BR5: None | BS5: No | BT5: None | BU5: 30% | BV5: Yes, peaceful. | BW5: Neither | BX5: Neither | BY5: Disagree | BZ5: Disagree | CA5: Agree | CB5: Disagree | CC5: Agree | CD5: Neither | CE5: Agree | CF5: Disagree | CG5: Agree | CH5: Neither | CI5: Disagree | CJ5: Disagree | CK5: Agree | CL5: Not at all | CM5: Moderately | CN5: Moderately | CO5: 261.74298 | CP5: 350.39098 | CQ5: 138.96897 | CR5: 0.52085246 | CS5: 0.011651432 | CT5: 0.027570822
A6: 5 | B6: German | C6: female | D6: 41 | E6: TE0+Sim+10 | F6: 15.12.2025 | G6: 0.56997685 | H6: 0.58055556 | I6: 0.58194444 | J6: 28.972654 | K6: 10.339274 | L6: 58.556133 | M6: 0.47933333 | N6: 0.0060679202 | O6: 0.015508198 | P6: 0.58261574 | Q6: 0.58356481 | R6: 6 | S6: 5 | T6: 308.2048 | U6: 407.62286 | V6: 39.627525 | W6: 0.50922034 | X6: 0.0069447329 | Y6: 0.019593465 | Z6: 0.58357639 | AA6: 0.5849537 | AB6: 33.550793 | AC6: 12.629758 | AD6: 48.813789 | AE6: 0.52852632 | AF6: 0.0063436717 | AG6: 0.017873394 | AH6: 0.58501157 | AI6: 0.58564815 | AJ6: 5 | AK6: 4 | AL6: 21.150519 | AM6: 16.472705 | AN6: 27.02278 | AO6: 0.51292683 | AP6: 0.0072101971 | AQ6: 0.023840529 | AR6: 0.58565972 | AS6: 0.58703704 | AT6: 21.969958 | AU6: 11.441075 | AV6: 58.695114 | AW6: 0.51556818 | AX6: 0.0063284513 | AY6: 0.017884752 | AZ6: 0.58680556 | BA6: 0.59027778 | BB6: soundscape | BC6: none | BD6: looking to a tv and hearing white noise | BE6: yes | BF6: 1980's television | BG6: no | BH6: none | BI6: yes | BJ6: living home of my firt home | BK6: yes | BL6: watching tv | BM6: yes | BN6: tv | BO6: yes | BP6: childhood | BQ6: no | BR6: none | BS6: yes | BT6: nervousness, axiety | BU6: 50% | BV6: nervousness, hectic | BW6: Disagree | BX6: Neither | BY6: Disagree | BZ6: Disagree | CA6: Disagree | CB6: Agree | CC6: Agree | CD6: Agree | CE6: Disagree | CF6: Neither | CG6: Neither | CH6: Disagree | CI6: Agree | CJ6: Agree | CK6: Disagree | CL6: Moderately | CM6: Not at all | CN6: Dominates completely | CO6: 29.986506 | CP6: 12.693112 | CQ6: 138.07837 | CR6: 0.48005882 | CS6: 0.0056512575 | CT6: 0.014101598
A7: 6 | B7: India | C7: male | D7: 28 | E7: TE0-10 | F7: 15.12.2025 | G7: 0.63626157 | H7: 0.64583333 | I7: 0.64791667 | J7: 92.388385 | K7: 88.920155 | L7: 89.808195 | M7: 0.5295188 | N7: 0.0041355701 | O7: 0.0078440294 | P7: 0.64792824 | Q7: 0.64930556 | R7: 7 | S7: 6 | T7: 92.642336 | U7: 96.45798 | V7: 59.121295 | W7: 0.48513636 | X7: 0.0063648068 | Y7: 0.010280178 | Z7: 0.64931713 | AA7: 0.65069444 | AB7: 91.29024 | AC7: 98.667714 | AD7: 58.876089 | AE7: 0.55055556 | AF7: 0.0046600175 | AG7: 0.0087585059 | AH7: 0.65070602 | AI7: 0.65200231 | AJ7: 7 | AK7: 6 | AL7: 60.928079 | AM7: 48.55955 | AN7: 55.338976 | AO7: 0.52834146 | AP7: 0.0050631018 | AQ7: 0.0087255142 | AR7: 0.65201389 | AS7: 0.65327546 | AT7: 87.844144 | AV7: 54.399025 | AW7: 0.509525 | AX7: 0.0052463005 | AY7: 0.0091657579 | AZ7: 0.65277778 | BA7: 0.65416667 | BB7: No | BC7: None | BD7: No | BE7: None | BF7: None | BG7: No | BH7: None | BI7: No | BJ7: None | BK7: No | BL7: None | BM7: No | BN7: None | BO7: No | BP7: None | BQ7: No | BR7: None | BS7: No | BT7: None | BU7: 95 | BV7: No | BW7: Disagree | BX7: Agree | BY7: Neither | BZ7: Disagree | CA7: Disagree | CB7: Agree | CC7: Agree | CD7: Agree | CE7: Strongly disagree | CF7: Agree | CG7: Disagree | CH7: Disagree | CI7: Agree | CJ7: Neither | CK7: Strongly disagree | CL7: Dominates completely | CM7: Not at all | CN7: A little | CO7: 158.53168 | CP7: 274.40751 | CQ7: 37.067214 | CR7: 0.52146429 | CS7: 0.0048705579 | CT7: 0.0089939769
A8: 7 | B8: German | C8: male | D8: 27 | E8: TE0 | F8: 16.12.2025 | G8: 0.45996528 | H8: 0.48194444 | I8: 0.48333333 | J8: 99.052153 | K8: 120.98148 | L8: 59.284565 | M8: 0.46715294 | N8: 0.012395531 | O8: 0.027485864 | P8: 0.48395833 | Q8: 0.48498843 | R8: 7 | S8: 6 | T8: 431.99072 | U8: 527.25741 | V8: 43.473373 | W8: 0.48173134 | X8: 0.012176046 | Y8: 0.032037796 | Z8: 0.485 | AA8: 0.48637731 | AB8: 71.663275 | AC8: 64.331696 | AD8: 58.908 | AE8: 0.54731818 | AF8: 0.0093997229 | AG8: 0.022936958 | AH8: 0.48638889 | AI8: 0.48743056 | AJ8: 7 | AK8: 6 | AL8: 607.42308 | AM8: 626.86601 | AN8: 44.545791 | AO8: 0.54501493 | AP8: 0.010443029 | AQ8: 0.029243915 | AR8: 0.4875 | AS8: 0.48888889 | AT8: 72.698338 | AU8: 46.109359 | AV8: 58.473218 | AW8: 0.51085057 | AX8: 0.0078349503 | AY8: 0.020876693 | AZ8: 0.48888889 | BA8: 0.49166667 | BB8: nein | BC8: keine | BD8: keine | BE8: nein | BF8: keine | BG8: nein | BH8: keine | BI8: ja | BJ8: Straße, laufen in der Stadt | BK8: ja | BL8: Fahrrad fahren, joggen | BM8: nein | BN8: keine | BO8: ja | BP8: Herbst, kältere Jahreszeit | BQ8: nein | BR8: keine | BS8: nein | BT8: keine | BU8: 100 | BV8: nein | BW8: Weder noch | BX8: Stimme nicht zu | BY8: Stimme zu | BZ8: Stimme zu | CA8: Stimme zu | CB8: Stimme zu | CC8: Stimme nicht zu | CD8: Stimme zu | CE8: Stimme zu | CF8: Stimme nicht zu | CH8: Stimme zu | CI8: Stimme nicht zu | CJ8: Stimme nicht zu | CK8: Stimme nicht zu | CL8: Vollständig dominierend | CM8: Gar nicht | CN8: Gar nicht | CO8: 56.58452 | CP8: 39.711322 | CQ8: 121.08181 | CR8: 0.56145029 | CS8: 0.0097711961 | CT8: 0.023078796
